Workbook

Sheet Instrucciones
A1: Registro y cálculo de métricas de calidad ISO/IEC 25010
A2: Producto evaluado: VigiSalud Malaria (https://vigisalud-malaria.vercel.app)
A3: Curso: Calidad de Software – Trabajo Parcial 6 – UNSA, 2026-B
A4: Equipo: Cari Quispe, Juan Manuel; Chura Monroy, Daniel Wilston; Lopez Arela, Ower Frank; Phocco Tapia, Alejandro Josue; Zegarra Puma, Mauricio Eduardo
A6: Cómo usar el libro
A7: 1. 'Modelo': características y subcaracterísticas adoptadas, prioridad y justificación (Punto 1).
A8: 2. 'Métricas': fichas GQM con objetivo, pregunta, fórmula, umbral y responsable (Punto 2).
A9: 3. 'Registro': una fila por métrica y corrida con los campos del formato de recopilación (Punto 3).
A10: Ingrese A y B (o el valor medido). Resultado, estado, puntaje y categoría se calculan con fórmulas.
A11: 4. 'Incidentes': fallos clasificados por origen (producto, script de prueba, infraestructura).
A12: 5. 'Resumen': conteos por característica y corrida, calculados con fórmulas (insumo del tablero, Punto 4).
A13: 6. 'Requisitos': matriz de trazabilidad requisito → métrica → prueba.
... A18: Los umbrales se fijaron el 27/10/2026, antes de la corrida 01.

Sheet Modelo
A1: Código | B1: Característica | C1: Prioridad | D1: Justificación | E1: Subcaracterística | F1: Estado | G1: Métricas / motivo
A2: IF | B2: Idoneidad funcional | C2: Alta | D2: Un sistema de vigilancia que muestra cifras incorrectas lleva a decisiones sanitarias erróneas; la corrección de los conteos es el requisito central. | E2: Completitud funcional | F2: seleccionada | G2: IF-01
A3: IF | B3: Idoneidad funcional | C3: Alta | D3: Un sistema de vigilancia que muestra cifras incorrectas lleva a decisiones sanitarias erróneas; la corrección de los conteos es el requisito central. | E3: Corrección funcional | F3: seleccionada | G3: IF-02
A4: IF | B4: Idoneidad funcional | C4: Alta | D4: Un sistema de vigilancia que muestra cifras incorrectas lleva a decisiones sanitarias erróneas; la corrección de los conteos es el requisito central. | E4: Pertinencia funcional | F4: seleccionada | G4: IF-03
A5: ED | B5: Eficiencia de desempeño | C5: Media | D5: El personal de epidemiología de establecimientos amazónicos trabaja con conexiones móviles lentas; la carga y la respuesta a filtros deben ser rápidas. | E5: Comportamiento temporal | F5: seleccionada | G5: ED-01, ED-02
A6: ED | B6: Eficiencia de desempeño | C6: Media | D6: El personal de epidemiología de establecimientos amazónicos trabaja con conexiones móviles lentas; la carga y la respuesta a filtros deben ser rápidas. | E6: Utilización de recursos | F6: seleccionada | G6: ED-03
A7: ED | B7: Eficiencia de desempeño | C7: Media | D7: El personal de epidemiología de establecimientos amazónicos trabaja con conexiones móviles lentas; la carga y la respuesta a filtros deben ser rápidas. | E7: Capacidad | F7: no aplicable | G7: Sitio estático servido por la red de distribución de Vercel; no hay servidor propio ni usuarios concurrentes que limitar.
A8: CO | B8: Compatibilidad | C8: Baja | D8: Los analistas reutilizan los datos en Excel u otros sistemas; basta con que las exportaciones sean interoperables. | E8: Interoperabilidad | F8: seleccionada | G8: CO-01
A9: CO | B9: Compatibilidad | C9: Baja | D9: Los analistas reutilizan los datos en Excel u otros sistemas; basta con que las exportaciones sean interoperables. | E9: Coexistencia | F9: no aplicable | G9: Se ejecuta en el navegador sin compartir recursos con otros productos instalados.
A10: CI | B10: Capacidad de interacción | C10: Alta | D10: Lo usan personas con distinta formación y posibles discapacidades; los errores de uso no deben producir conclusiones falsas. | E10: Operabilidad | F10: seleccionada | G10: CI-01
A11: CI | B11: Capacidad de interacción | C11: Alta | D11: Lo usan personas con distinta formación y posibles discapacidades; los errores de uso no deben producir conclusiones falsas. | E11: Protección contra errores de usuario | F11: seleccionada | G11: CI-02
A12: CI | B12: Capacidad de interacción | C12: Alta | D12: Lo usan personas con distinta formación y posibles discapacidades; los errores de uso no deben producir conclusiones falsas. | E12: Inclusividad | F12: seleccionada | G12: CI-03
... A39: SO | B39: Seguridad operacional | C39: Alta | D39: En salud pública, una cifra mal interpretada puede retrasar una respuesta a un brote; el sistema debe advertir sus límites y fallar de forma segura. | E39: Integración segura | F39: no aplicable | G39: No se integra con otros sistemas en esta versión.

Sheet Métricas
A1: ID | B1: Característica | C1: Subcaracterística | D1: Métrica | E1: Objetivo (G) | F1: Pregunta (Q) | G1: A | H1: B | I1: Fórmula (M) | J1: Unidad | K1: Sentido | L1: Umbral | M1: Requisito | N1: Procedimiento | O1: Herramienta | P1: Responsable
A2: IF-01 | B2: Idoneidad funcional | C2: Completitud funcional | D2: Cobertura de requisitos funcionales | E2: Asegurar que el dashboard ofrece todas las funciones especificadas. | F2: ¿Qué proporción de los requisitos funcionales especificados pasa su prueba de aceptación? | G2: Requisitos funcionales con prueba E2E aprobada | H2: Requisitos funcionales especificados (RF-01 a RF-15) | I2: X = A/B × 100 | J2: % | K2: mayor | L2: 95 | M2: RF-01…RF-15 | N2: evaluacion/pruebas/funcional.spec.js (un caso por RF) | O2: Playwright 1.64 (Chromium) | P2: Chura Monroy, Daniel Wilston
A3: IF-02 | B3: Idoneidad funcional | C3: Corrección funcional | D3: Exactitud frente al oráculo oficial | E3: Verificar que cada cifra mostrada coincide con la calculada directamente de los CSV del MINSA. | F3: ¿Qué proporción de los valores verificados coincide con el oráculo independiente? | G3: Valores mostrados iguales al oráculo | H3: Valores verificados (8 escenarios × campos) | I3: X = A/B × 100 | J3: % | K3: mayor | L3: 100 | M3: RNF-01 exactitud | N3: evaluacion/oraculo.py + evaluacion/pruebas/oraculo.spec.js | O3: Python 3.12 + Playwright | P3: Chura Monroy, Daniel Wilston
A4: IF-03 | B4: Idoneidad funcional | C4: Pertinencia funcional | D4: Cobertura de las dimensiones de vigilancia | E4: Comprobar que el producto responde a las preguntas de la vigilancia: tiempo, lugar y persona. | F4: ¿Qué proporción de las dimensiones de análisis epidemiológico ofrece el dashboard? | G4: Dimensiones presentes y funcionales | H4: Dimensiones requeridas (tendencia, semana epidemiológica, canal endémico, departamento, distrito, edad, sexo, especie) | I4: X = A/B × 100 | J4: % | K4: mayor | L4: 90 | M4: RNF-02 pertinencia | N4: Lista de verificación automatizada en interaccion.spec.js | O4: Playwright | P4: Chura Monroy, Daniel Wilston
A5: ED-01 | B5: Eficiencia de desempeño | C5: Comportamiento temporal | D5: Largest Contentful Paint (móvil) | E5: Que el contenido principal aparezca rápido incluso con red móvil. | F5: ¿Cuánto tarda en mostrarse el contenido principal en un móvil con red 4G lenta simulada? | G5: LCP mediano de 3 ejecuciones de Lighthouse (perfil móvil) | H5: — | I5: X = valor medido | J5: s | K5: menor | L5: 2.5 | M5: RNF-03 carga | N5: evaluacion/scripts/lighthouse.mjs | O5: Lighthouse 12.8 | P5: Chura Monroy, Daniel Wilston
A6: ED-02 | B6: Eficiencia de desempeño | C6: Comportamiento temporal | D6: Tiempo de respuesta a filtros | E6: Que el análisis interactivo sea fluido. | F6: ¿Cuánto tarda el dashboard en volver a dibujarse tras cambiar un filtro? | G6: Mediana de 20 cambios de filtro (ms, hasta el siguiente cuadro pintado) | H6: — | I6: X = valor medido | J6: ms | K6: menor | L6: 200 | M6: RNF-03 respuesta | N6: evaluacion/pruebas/rendimiento.spec.js | O6: Playwright + Performance API | P6: Chura Monroy, Daniel Wilston
A7: ED-03 | B7: Eficiencia de desempeño | C7: Utilización de recursos | D7: Peso transferido en la carga inicial | E7: Limitar el consumo de datos móviles. | F7: ¿Cuántos KB descarga el navegador para mostrar el dashboard? | G7: total-byte-weight de Lighthouse (KB, mediana) | H7: — | I7: X = valor medido | J7: KB | K7: menor | L7: 1000 | M7: RNF-04 consumo | N7: evaluacion/scripts/lighthouse.mjs | O7: Lighthouse 12.8 | P7: Chura Monroy, Daniel Wilston
A8: CO-01 | B8: Compatibilidad | C8: Interoperabilidad | D8: Exportaciones válidas y consistentes | E8: Permitir reutilizar los datos filtrados en otras herramientas. | F8: ¿Qué proporción de las exportaciones se puede leer con un parser estándar y suma los mismos casos que la interfaz? | G8: Exportaciones válidas y consistentes | H8: Exportaciones probadas (CSV y JSON en 2 escenarios) | I8: X = A/B × 100 | J8: % | K8: mayor | L8: 100 | M8: RF-11 | N8: evaluacion/pruebas/funcional.spec.js (RF-11) | O8: Playwright | P8: Chura Monroy, Daniel Wilston
A9: CI-01 | B9: Capacidad de interacción | C9: Operabilidad | D9: Controles operables con teclado | E9: Que todas las funciones se puedan usar sin ratón. | F9: ¿Qué proporción de los controles interactivos se alcanza y opera solo con teclado? | G9: Controles alcanzados con Tab y operados con Enter/Espacio/flechas | H9: Controles interactivos de la página | I9: X = A/B × 100 | J9: % | K9: mayor | L9: 95 | M9: RNF-05 accesibilidad | N9: evaluacion/pruebas/interaccion.spec.js | O9: Playwright | P9: Lopez Arela, Ower Frank
A10: CI-02 | B10: Capacidad de interacción | C10: Protección contra errores de usuario | D10: Entradas inválidas controladas | E10: Que un enlace o filtro mal escrito no rompa el sistema ni muestre datos engañosos. | F10: ¿Qué proporción de entradas inválidas se rechaza con aviso y valores por defecto? | G10: Casos inválidos controlados con aviso | H10: Casos inválidos probados | I10: X = A/B × 100 | J10: % | K10: mayor | L10: 100 | M10: RNF-06 | N10: evaluacion/pruebas/interaccion.spec.js | O10: Playwright | P10: Lopez Arela, Ower Frank
A11: CI-03 | B11: Capacidad de interacción | C11: Inclusividad | D11: Violaciones WCAG graves | E11: Que personas con discapacidad puedan usar el sistema (WCAG 2.2 AA). | F11: ¿Cuántas violaciones críticas o serias detecta axe-core en las vistas evaluadas? | G11: Vistas sin violaciones críticas ni serias | H11: Vistas evaluadas (dashboard ES, EN, filtrado y tablero de calidad) | I11: X = A/B × 100 | J11: % | K11: mayor | L11: 100 | M11: RNF-05 accesibilidad | N11: evaluacion/pruebas/accesibilidad.spec.js | O11: axe-core 4 + Playwright | P11: Lopez Arela, Ower Frank
A12: CI-04 | B12: Capacidad de interacción | C12: Autodescriptividad | D12: Gráficos con alternativa textual | E12: Que cada gráfico se explique por sí mismo y tenga un equivalente en texto o tabla. | F12: ¿Qué proporción de los gráficos tiene descripción accesible y datos consultables? | G12: Gráficos con etiqueta accesible y tabla o lista equivalente | H12: Gráficos del dashboard | I12: X = A/B × 100 | J12: % | K12: mayor | L12: 100 | M12: RNF-05 | N12: evaluacion/pruebas/interaccion.spec.js | O12: Playwright | P12: Lopez Arela, Ower Frank
A13: FI-01 | B13: Fiabilidad | C13: Ausencia de fallos | D13: Ejecuciones sin errores de JavaScript | E13: Que el uso normal no produzca errores. | F13: ¿Qué proporción de las combinaciones navegador × pantalla recorre todo el dashboard sin errores de consola? | G13: Combinaciones sin errores | H13: Combinaciones probadas (3 navegadores × 3 pantallas) | I13: X = A/B × 100 | J13: % | K13: mayor | L13: 100 | M13: RNF-07 | N13: evaluacion/pruebas/adaptabilidad.spec.js | O13: Playwright (Chromium, Firefox, WebKit) | P13: Lopez Arela, Ower Frank
... A26: SO-03 | B26: Seguridad operacional | C26: Identificación de riesgos | D26: Limitaciones de la fuente señaladas | E26: Que el usuario conozca los límites de los datos antes de interpretarlos. | F26: ¿Qué proporción de las limitaciones conocidas de la fuente se señala en la interfaz? | G26: Limitaciones señaladas | H26: Limitaciones conocidas (cambio de fuente 2009, edad no disponible antes de 2009, casos no son tasas, canal endémico sin años suficientes) | I26: X = A/B × 100 | J26: % | K26: mayor | L26: 100 | M26: RNF-14 | N26: evaluacion/pruebas/interaccion.spec.js | O26: Playwright | P26: Lopez Arela, Ower Frank

Sheet Registro
A1: ID métrica | B1: Característica | C1: Subcaracterística | D1: Requisito | E1: Caso / procedimiento | F1: Corrida | G1: Versión | H1: Fecha | I1: Entorno / navegador | J1: Datos utilizados | K1: Tipo | L1: A | M1: B | N1: Fórmula | O1: Resultado X | P1: Unidad | Q1: Sentido | R1: Umbral | S1: Estado | T1: Puntaje | U1: Categoría | V1: Evidencia | W1: Responsable | X1: Incidente | Y1: Decisión | Z1: Observaciones
A2: IF-01 | B2: Idoneidad funcional | C2: Completitud funcional | D2: RF-01…RF-15 | E2: evaluacion/pruebas/funcional.spec.js (un caso por RF) | F2: 01 | G2: v1.0 (e2ec6c9) | H2: 2026-10-27T05:09:45.825Z | I2: Windows_NT 10.0.26300 · Node v22.14.0 · Playwright Version 1.64.1 · Lighthouse 12.8.2 | J2: datos_abiertos_vigilancia_malaria_2000_2008.csv sha256:749d8897e94255d0; datos_abiertos_vigilancia_malaria_2009_2025.csv sha256:084ef118bd67753d | K2: proporcion | L2: 14 | M2: 15 | N2: X = A / B × 100 | O2: =IF(L2="","",IF(K2="proporcion",ROUND(L2/M2*100,2),L2)) -> 93.33 | P2: % | Q2: mayor | R2: 95 | S2: =IF(O2="","Pendiente",IF(Q2="mayor",IF(O2>=R2,"Aprobado","Rechazado"),IF(O2<=R2,"Aprobado","Rechazado"))) -> Rechazado | T2: =IF(O2="","",IF(K2="proporcion",O2,MIN(100,ROUND(100*R2/MAX(O2,0.000001),2)))) -> 93.33 | U2: =IF(T2="","",IF(T2<40,"No aceptable",IF(T2<60,"Mínimamente aceptable",IF(T2<90,"Rango objetivo","Supera los requisitos")))) -> Supera los requisitos | V2: evaluacion/resultados/corrida-01/playwright.json, reporte-html/ | W2: Chura Monroy, Daniel Wilston | X2: INC-04 | Y2: El script usa ahora #fEsp button[data-v=…], acotado al grupo de filtros.
A3: IF-01 | B3: Idoneidad funcional | C3: Completitud funcional | D3: RF-01…RF-15 | E3: evaluacion/pruebas/funcional.spec.js (un caso por RF) | F3: 02 | G3: v1.1 (a63333f) | H3: 2026-10-27T05:22:39.464Z | I3: Windows_NT 10.0.26300 · Node v22.14.0 · Playwright Version 1.64.1 · Lighthouse 12.8.2 | J3: datos_abiertos_vigilancia_malaria_2000_2008.csv sha256:749d8897e94255d0; datos_abiertos_vigilancia_malaria_2009_2025.csv sha256:084ef118bd67753d | K3: proporcion | L3: 15 | M3: 15 | N3: X = A / B × 100 | O3: =IF(L3="","",IF(K3="proporcion",ROUND(L3/M3*100,2),L3)) -> 100 | P3: % | Q3: mayor | R3: 95 | S3: =IF(O3="","Pendiente",IF(Q3="mayor",IF(O3>=R3,"Aprobado","Rechazado"),IF(O3<=R3,"Aprobado","Rechazado"))) -> Aprobado | T3: =IF(O3="","",IF(K3="proporcion",O3,MIN(100,ROUND(100*R3/MAX(O3,0.000001),2)))) -> 100 | U3: =IF(T3="","",IF(T3<40,"No aceptable",IF(T3<60,"Mínimamente aceptable",IF(T3<90,"Rango objetivo","Supera los requisitos")))) -> Supera los requisitos | V3: evaluacion/resultados/corrida-02/playwright.json, reporte-html/ | W3: Chura Monroy, Daniel Wilston | Y3: Aceptar
A4: IF-01 | B4: Idoneidad funcional | C4: Completitud funcional | D4: RF-01…RF-15 | E4: evaluacion/pruebas/funcional.spec.js (un caso por RF) | F4: 03 | G4: v1.2 (ecfaca3) | H4: 2026-10-27T11:13:27.260Z | I4: Windows_NT 10.0.26300 · Node v22.14.0 · Playwright Version 1.64.1 · Lighthouse 12.8.2 | J4: datos_abiertos_vigilancia_malaria_2000_2008.csv sha256:749d8897e94255d0; datos_abiertos_vigilancia_malaria_2009_2025.csv sha256:084ef118bd67753d | K4: proporcion | L4: 15 | M4: 15 | N4: X = A / B × 100 | O4: =IF(L4="","",IF(K4="proporcion",ROUND(L4/M4*100,2),L4)) -> 100 | P4: % | Q4: mayor | R4: 95 | S4: =IF(O4="","Pendiente",IF(Q4="mayor",IF(O4>=R4,"Aprobado","Rechazado"),IF(O4<=R4,"Aprobado","Rechazado"))) -> Aprobado | T4: =IF(O4="","",IF(K4="proporcion",O4,MIN(100,ROUND(100*R4/MAX(O4,0.000001),2)))) -> 100 | U4: =IF(T4="","",IF(T4<40,"No aceptable",IF(T4<60,"Mínimamente aceptable",IF(T4<90,"Rango objetivo","Supera los requisitos")))) -> Supera los requisitos | V4: evaluacion/resultados/corrida-03/playwright.json, reporte-html/ | W4: Chura Monroy, Daniel Wilston | Y4: Aceptar
A5: IF-01 | B5: Idoneidad funcional | C5: Completitud funcional | D5: RF-01…RF-15 | E5: evaluacion/pruebas/funcional.spec.js (un caso por RF) | F5: 04 | G5: v1.3 (1219f7a) | H5: 2026-10-27T11:22:57.351Z | I5: Windows_NT 10.0.26300 · Node v22.14.0 · Playwright Version 1.64.1 · Lighthouse 12.8.2 | J5: datos_abiertos_vigilancia_malaria_2000_2008.csv sha256:749d8897e94255d0; datos_abiertos_vigilancia_malaria_2009_2025.csv sha256:084ef118bd67753d | K5: proporcion | L5: 15 | M5: 15 | N5: X = A / B × 100 | O5: =IF(L5="","",IF(K5="proporcion",ROUND(L5/M5*100,2),L5)) -> 100 | P5: % | Q5: mayor | R5: 95 | S5: =IF(O5="","Pendiente",IF(Q5="mayor",IF(O5>=R5,"Aprobado","Rechazado"),IF(O5<=R5,"Aprobado","Rechazado"))) -> Aprobado | T5: =IF(O5="","",IF(K5="proporcion",O5,MIN(100,ROUND(100*R5/MAX(O5,0.000001),2)))) -> 100 | U5: =IF(T5="","",IF(T5<40,"No aceptable",IF(T5<60,"Mínimamente aceptable",IF(T5<90,"Rango objetivo","Supera los requisitos")))) -> Supera los requisitos | V5: evaluacion/resultados/corrida-04/playwright.json, reporte-html/ | W5: Chura Monroy, Daniel Wilston | Y5: Aceptar
A6: IF-01 | B6: Idoneidad funcional | C6: Completitud funcional | D6: RF-01…RF-15 | E6: evaluacion/pruebas/funcional.spec.js (un caso por RF) | F6: 05 | G6: v1.4 (ecd9c46) | H6: 2026-10-27T11:34:29.914Z | I6: Windows_NT 10.0.26300 · Node v22.14.0 · Playwright Version 1.64.1 · Lighthouse 12.8.2 | J6: datos_abiertos_vigilancia_malaria_2000_2008.csv sha256:749d8897e94255d0; datos_abiertos_vigilancia_malaria_2009_2025.csv sha256:084ef118bd67753d | K6: proporcion | L6: 15 | M6: 15 | N6: X = A / B × 100 | O6: =IF(L6="","",IF(K6="proporcion",ROUND(L6/M6*100,2),L6)) -> 100 | P6: % | Q6: mayor | R6: 95 | S6: =IF(O6="","Pendiente",IF(Q6="mayor",IF(O6>=R6,"Aprobado","Rechazado"),IF(O6<=R6,"Aprobado","Rechazado"))) -> Aprobado | T6: =IF(O6="","",IF(K6="proporcion",O6,MIN(100,ROUND(100*R6/MAX(O6,0.000001),2)))) -> 100 | U6: =IF(T6="","",IF(T6<40,"No aceptable",IF(T6<60,"Mínimamente aceptable",IF(T6<90,"Rango objetivo","Supera los requisitos")))) -> Supera los requisitos | V6: evaluacion/resultados/corrida-05/playwright.json, reporte-html/ | W6: Chura Monroy, Daniel Wilston | Y6: Aceptar
A7: IF-01 | B7: Idoneidad funcional | C7: Completitud funcional | D7: RF-01…RF-15 | E7: evaluacion/pruebas/funcional.spec.js (un caso por RF) | F7: 06 | G7: v1.5 (2aca5a2) | H7: 2026-10-27T11:44:29.601Z | I7: Windows_NT 10.0.26300 · Node v22.14.0 · Playwright Version 1.64.1 · Lighthouse 12.8.2 | J7: datos_abiertos_vigilancia_malaria_2000_2008.csv sha256:749d8897e94255d0; datos_abiertos_vigilancia_malaria_2009_2025.csv sha256:084ef118bd67753d | K7: proporcion | L7: 15 | M7: 15 | N7: X = A / B × 100 | O7: =IF(L7="","",IF(K7="proporcion",ROUND(L7/M7*100,2),L7)) -> 100 | P7: % | Q7: mayor | R7: 95 | S7: =IF(O7="","Pendiente",IF(Q7="mayor",IF(O7>=R7,"Aprobado","Rechazado"),IF(O7<=R7,"Aprobado","Rechazado"))) -> Aprobado | T7: =IF(O7="","",IF(K7="proporcion",O7,MIN(100,ROUND(100*R7/MAX(O7,0.000001),2)))) -> 100 | U7: =IF(T7="","",IF(T7<40,"No aceptable",IF(T7<60,"Mínimamente aceptable",IF(T7<90,"Rango objetivo","Supera los requisitos")))) -> Supera los requisitos | V7: evaluacion/resultados/corrida-06/playwright.json, reporte-html/ | W7: Chura Monroy, Daniel Wilston | Y7: Aceptar
A8: IF-01 | B8: Idoneidad funcional | C8: Completitud funcional | D8: RF-01…RF-15 | E8: evaluacion/pruebas/funcional.spec.js (un caso por RF) | F8: 07 | G8: v1.6 (f47b30f) | H8: 2026-10-27T11:55:54.129Z | I8: Windows_NT 10.0.26300 · Node v22.14.0 · Playwright Version 1.64.1 · Lighthouse 12.8.2 | J8: datos_abiertos_vigilancia_malaria_2000_2008.csv sha256:749d8897e94255d0; datos_abiertos_vigilancia_malaria_2009_2025.csv sha256:084ef118bd67753d | K8: proporcion | L8: 15 | M8: 15 | N8: X = A / B × 100 | O8: =IF(L8="","",IF(K8="proporcion",ROUND(L8/M8*100,2),L8)) -> 100 | P8: % | Q8: mayor | R8: 95 | S8: =IF(O8="","Pendiente",IF(Q8="mayor",IF(O8>=R8,"Aprobado","Rechazado"),IF(O8<=R8,"Aprobado","Rechazado"))) -> Aprobado | T8: =IF(O8="","",IF(K8="proporcion",O8,MIN(100,ROUND(100*R8/MAX(O8,0.000001),2)))) -> 100 | U8: =IF(T8="","",IF(T8<40,"No aceptable",IF(T8<60,"Mínimamente aceptable",IF(T8<90,"Rango objetivo","Supera los requisitos")))) -> Supera los requisitos | V8: evaluacion/resultados/corrida-07/playwright.json, reporte-html/ | W8: Chura Monroy, Daniel Wilston | X8: INC-21 | Y8: Se agregaron las versiones en inglés en modelo.json y requisitos.json y un diccionario de motivos en i18n.js, y el tablero y el dashboard las usan. El barrido ya no encuentra textos de interfaz en español; quedan solo nombres propios, como el título oficial del conjunto de datos y los topónimos. Se recomienda incorporar ese barrido a la prueba de RF-13. Se verifica en la corrida 08.
A9: IF-01 | B9: Idoneidad funcional | C9: Completitud funcional | D9: RF-01…RF-15 | E9: evaluacion/pruebas/funcional.spec.js (un caso por RF) | F9: 08 | G9: v1.7 (b0ac637) | H9: 2026-10-27T12:06:18.210Z | I9: Windows_NT 10.0.26300 · Node v22.14.0 · Playwright Version 1.64.1 · Lighthouse 12.8.2 | J9: datos_abiertos_vigilancia_malaria_2000_2008.csv sha256:749d8897e94255d0; datos_abiertos_vigilancia_malaria_2009_2025.csv sha256:084ef118bd67753d | K9: proporcion | L9: 15 | M9: 15 | N9: X = A / B × 100 | O9: =IF(L9="","",IF(K9="proporcion",ROUND(L9/M9*100,2),L9)) -> 100 | P9: % | Q9: mayor | R9: 95 | S9: =IF(O9="","Pendiente",IF(Q9="mayor",IF(O9>=R9,"Aprobado","Rechazado"),IF(O9<=R9,"Aprobado","Rechazado"))) -> Aprobado | T9: =IF(O9="","",IF(K9="proporcion",O9,MIN(100,ROUND(100*R9/MAX(O9,0.000001),2)))) -> 100 | U9: =IF(T9="","",IF(T9<40,"No aceptable",IF(T9<60,"Mínimamente aceptable",IF(T9<90,"Rango objetivo","Supera los requisitos")))) -> Supera los requisitos | V9: evaluacion/resultados/corrida-08/playwright.json, reporte-html/ | W9: Chura Monroy, Daniel Wilston | X9: INC-22 | Y9: El tablero traduce la prioridad (High, Medium, Low). Se amplió el barrido con todos los valores enumerados del modelo (prioridad, estado, origen), y ya no encuentra restos. Se verifica en la corrida 09.
A10: IF-01 | B10: Idoneidad funcional | C10: Completitud funcional | D10: RF-01…RF-15 | E10: evaluacion/pruebas/funcional.spec.js (un caso por RF) | F10: 09 | G10: v1.8 (ed65ebc) | H10: 2026-10-27T12:16:43.263Z | I10: Windows_NT 10.0.26300 · Node v22.14.0 · Playwright Version 1.64.1 · Lighthouse 12.8.2 | J10: datos_abiertos_vigilancia_malaria_2000_2008.csv sha256:749d8897e94255d0; datos_abiertos_vigilancia_malaria_2009_2025.csv sha256:084ef118bd67753d | K10: proporcion | L10: 15 | M10: 15 | N10: X = A / B × 100 | O10: =IF(L10="","",IF(K10="proporcion",ROUND(L10/M10*100,2),L10)) -> 100 | P10: % | Q10: mayor | R10: 95 | S10: =IF(O10="","Pendiente",IF(Q10="mayor",IF(O10>=R10,"Aprobado","Rechazado"),IF(O10<=R10,"Aprobado","Rechazado"))) -> Aprobado | T10: =IF(O10="","",IF(K10="proporcion",O10,MIN(100,ROUND(100*R10/MAX(O10,0.000001),2)))) -> 100 | U10: =IF(T10="","",IF(T10<40,"No aceptable",IF(T10<60,"Mínimamente aceptable",IF(T10<90,"Rango objetivo","Supera los requisitos")))) -> Supera los requisitos | V10: evaluacion/resultados/corrida-09/playwright.json, reporte-html/ | W10: Chura Monroy, Daniel Wilston | Y10: Aceptar
A11: IF-02 | B11: Idoneidad funcional | C11: Corrección funcional | D11: RNF-01 exactitud | E11: evaluacion/oraculo.py + evaluacion/pruebas/oraculo.spec.js | F11: 01 | G11: v1.0 (e2ec6c9) | H11: 2026-10-27T05:09:45.825Z | I11: Windows_NT 10.0.26300 · Node v22.14.0 · Playwright Version 1.64.1 · Lighthouse 12.8.2 | J11: datos_abiertos_vigilancia_malaria_2000_2008.csv sha256:749d8897e94255d0; datos_abiertos_vigilancia_malaria_2009_2025.csv sha256:084ef118bd67753d | K11: proporcion | L11: 84 | M11: 84 | N11: X = A / B × 100 | O11: =IF(L11="","",IF(K11="proporcion",ROUND(L11/M11*100,2),L11)) -> 100 | P11: % | Q11: mayor | R11: 100 | S11: =IF(O11="","Pendiente",IF(Q11="mayor",IF(O11>=R11,"Aprobado","Rechazado"),IF(O11<=R11,"Aprobado","Rechazado"))) -> Aprobado | T11: =IF(O11="","",IF(K11="proporcion",O11,MIN(100,ROUND(100*R11/MAX(O11,0.000001),2)))) -> 100 | U11: =IF(T11="","",IF(T11<40,"No aceptable",IF(T11<60,"Mínimamente aceptable",IF(T11<90,"Rango objetivo","Supera los requisitos")))) -> Supera los requisitos | V11: evaluacion/resultados/corrida-01/if02-oraculo.json | W11: Chura Monroy, Daniel Wilston | Y11: Aceptar
A12: IF-02 | B12: Idoneidad funcional | C12: Corrección funcional | D12: RNF-01 exactitud | E12: evaluacion/oraculo.py + evaluacion/pruebas/oraculo.spec.js | F12: 02 | G12: v1.1 (a63333f) | H12: 2026-10-27T05:22:39.464Z | I12: Windows_NT 10.0.26300 · Node v22.14.0 · Playwright Version 1.64.1 · Lighthouse 12.8.2 | J12: datos_abiertos_vigilancia_malaria_2000_2008.csv sha256:749d8897e94255d0; datos_abiertos_vigilancia_malaria_2009_2025.csv sha256:084ef118bd67753d | K12: proporcion | L12: 84 | M12: 84 | N12: X = A / B × 100 | O12: =IF(L12="","",IF(K12="proporcion",ROUND(L12/M12*100,2),L12)) -> 100 | P12: % | Q12: mayor | R12: 100 | S12: =IF(O12="","Pendiente",IF(Q12="mayor",IF(O12>=R12,"Aprobado","Rechazado"),IF(O12<=R12,"Aprobado","Rechazado"))) -> Aprobado | T12: =IF(O12="","",IF(K12="proporcion",O12,MIN(100,ROUND(100*R12/MAX(O12,0.000001),2)))) -> 100 | U12: =IF(T12="","",IF(T12<40,"No aceptable",IF(T12<60,"Mínimamente aceptable",IF(T12<90,"Rango objetivo","Supera los requisitos")))) -> Supera los requisitos | V12: evaluacion/resultados/corrida-02/if02-oraculo.json | W12: Chura Monroy, Daniel Wilston | Y12: Aceptar
A13: IF-02 | B13: Idoneidad funcional | C13: Corrección funcional | D13: RNF-01 exactitud | E13: evaluacion/oraculo.py + evaluacion/pruebas/oraculo.spec.js | F13: 03 | G13: v1.2 (ecfaca3) | H13: 2026-10-27T11:13:27.260Z | I13: Windows_NT 10.0.26300 · Node v22.14.0 · Playwright Version 1.64.1 · Lighthouse 12.8.2 | J13: datos_abiertos_vigilancia_malaria_2000_2008.csv sha256:749d8897e94255d0; datos_abiertos_vigilancia_malaria_2009_2025.csv sha256:084ef118bd67753d | K13: proporcion | L13: 84 | M13: 84 | N13: X = A / B × 100 | O13: =IF(L13="","",IF(K13="proporcion",ROUND(L13/M13*100,2),L13)) -> 100 | P13: % | Q13: mayor | R13: 100 | S13: =IF(O13="","Pendiente",IF(Q13="mayor",IF(O13>=R13,"Aprobado","Rechazado"),IF(O13<=R13,"Aprobado","Rechazado"))) -> Aprobado | T13: =IF(O13="","",IF(K13="proporcion",O13,MIN(100,ROUND(100*R13/MAX(O13,0.000001),2)))) -> 100 | U13: =IF(T13="","",IF(T13<40,"No aceptable",IF(T13<60,"Mínimamente aceptable",IF(T13<90,"Rango objetivo","Supera los requisitos")))) -> Supera los requisitos | V13: evaluacion/resultados/corrida-03/if02-oraculo.json | W13: Chura Monroy, Daniel Wilston | Y13: Aceptar
A14: IF-02 | B14: Idoneidad funcional | C14: Corrección funcional | D14: RNF-01 exactitud | E14: evaluacion/oraculo.py + evaluacion/pruebas/oraculo.spec.js | F14: 04 | G14: v1.3 (1219f7a) | H14: 2026-10-27T11:22:57.351Z | I14: Windows_NT 10.0.26300 · Node v22.14.0 · Playwright Version 1.64.1 · Lighthouse 12.8.2 | J14: datos_abiertos_vigilancia_malaria_2000_2008.csv sha256:749d8897e94255d0; datos_abiertos_vigilancia_malaria_2009_2025.csv sha256:084ef118bd67753d | K14: proporcion | L14: 84 | M14: 84 | N14: X = A / B × 100 | O14: =IF(L14="","",IF(K14="proporcion",ROUND(L14/M14*100,2),L14)) -> 100 | P14: % | Q14: mayor | R14: 100 | S14: =IF(O14="","Pendiente",IF(Q14="mayor",IF(O14>=R14,"Aprobado","Rechazado"),IF(O14<=R14,"Aprobado","Rechazado"))) -> Aprobado | T14: =IF(O14="","",IF(K14="proporcion",O14,MIN(100,ROUND(100*R14/MAX(O14,0.000001),2)))) -> 100 | U14: =IF(T14="","",IF(T14<40,"No aceptable",IF(T14<60,"Mínimamente aceptable",IF(T14<90,"Rango objetivo","Supera los requisitos")))) -> Supera los requisitos | V14: evaluacion/resultados/corrida-04/if02-oraculo.json | W14: Chura Monroy, Daniel Wilston | Y14: Aceptar
A15: IF-02 | B15: Idoneidad funcional | C15: Corrección funcional | D15: RNF-01 exactitud | E15: evaluacion/oraculo.py + evaluacion/pruebas/oraculo.spec.js | F15: 05 | G15: v1.4 (ecd9c46) | H15: 2026-10-27T11:34:29.914Z | I15: Windows_NT 10.0.26300 · Node v22.14.0 · Playwright Version 1.64.1 · Lighthouse 12.8.2 | J15: datos_abiertos_vigilancia_malaria_2000_2008.csv sha256:749d8897e94255d0; datos_abiertos_vigilancia_malaria_2009_2025.csv sha256:084ef118bd67753d | K15: proporcion | L15: 84 | M15: 84 | N15: X = A / B × 100 | O15: =IF(L15="","",IF(K15="proporcion",ROUND(L15/M15*100,2),L15)) -> 100 | P15: % | Q15: mayor | R15: 100 | S15: =IF(O15="","Pendiente",IF(Q15="mayor",IF(O15>=R15,"Aprobado","Rechazado"),IF(O15<=R15,"Aprobado","Rechazado"))) -> Aprobado | T15: =IF(O15="","",IF(K15="proporcion",O15,MIN(100,ROUND(100*R15/MAX(O15,0.000001),2)))) -> 100 | U15: =IF(T15="","",IF(T15<40,"No aceptable",IF(T15<60,"Mínimamente aceptable",IF(T15<90,"Rango objetivo","Supera los requisitos")))) -> Supera los requisitos | V15: evaluacion/resultados/corrida-05/if02-oraculo.json | W15: Chura Monroy, Daniel Wilston | Y15: Aceptar
A16: IF-02 | B16: Idoneidad funcional | C16: Corrección funcional | D16: RNF-01 exactitud | E16: evaluacion/oraculo.py + evaluacion/pruebas/oraculo.spec.js | F16: 06 | G16: v1.5 (2aca5a2) | H16: 2026-10-27T11:44:29.601Z | I16: Windows_NT 10.0.26300 · Node v22.14.0 · Playwright Version 1.64.1 · Lighthouse 12.8.2 | J16: datos_abiertos_vigilancia_malaria_2000_2008.csv sha256:749d8897e94255d0; datos_abiertos_vigilancia_malaria_2009_2025.csv sha256:084ef118bd67753d | K16: proporcion | L16: 84 | M16: 84 | N16: X = A / B × 100 | O16: =IF(L16="","",IF(K16="proporcion",ROUND(L16/M16*100,2),L16)) -> 100 | P16: % | Q16: mayor | R16: 100 | S16: =IF(O16="","Pendiente",IF(Q16="mayor",IF(O16>=R16,"Aprobado","Rechazado"),IF(O16<=R16,"Aprobado","Rechazado"))) -> Aprobado | T16: =IF(O16="","",IF(K16="proporcion",O16,MIN(100,ROUND(100*R16/MAX(O16,0.000001),2)))) -> 100 | U16: =IF(T16="","",IF(T16<40,"No aceptable",IF(T16<60,"Mínimamente aceptable",IF(T16<90,"Rango objetivo","Supera los requisitos")))) -> Supera los requisitos | V16: evaluacion/resultados/corrida-06/if02-oraculo.json | W16: Chura Monroy, Daniel Wilston | Y16: Aceptar
A17: IF-02 | B17: Idoneidad funcional | C17: Corrección funcional | D17: RNF-01 exactitud | E17: evaluacion/oraculo.py + evaluacion/pruebas/oraculo.spec.js | F17: 07 | G17: v1.6 (f47b30f) | H17: 2026-10-27T11:55:54.129Z | I17: Windows_NT 10.0.26300 · Node v22.14.0 · Playwright Version 1.64.1 · Lighthouse 12.8.2 | J17: datos_abiertos_vigilancia_malaria_2000_2008.csv sha256:749d8897e94255d0; datos_abiertos_vigilancia_malaria_2009_2025.csv sha256:084ef118bd67753d | K17: proporcion | L17: 84 | M17: 84 | N17: X = A / B × 100 | O17: =IF(L17="","",IF(K17="proporcion",ROUND(L17/M17*100,2),L17)) -> 100 | P17: % | Q17: mayor | R17: 100 | S17: =IF(O17="","Pendiente",IF(Q17="mayor",IF(O17>=R17,"Aprobado","Rechazado"),IF(O17<=R17,"Aprobado","Rechazado"))) -> Aprobado | T17: =IF(O17="","",IF(K17="proporcion",O17,MIN(100,ROUND(100*R17/MAX(O17,0.000001),2)))) -> 100 | U17: =IF(T17="","",IF(T17<40,"No aceptable",IF(T17<60,"Mínimamente aceptable",IF(T17<90,"Rango objetivo","Supera los requisitos")))) -> Supera los requisitos | V17: evaluacion/resultados/corrida-07/if02-oraculo.json | W17: Chura Monroy, Daniel Wilston | Y17: Aceptar
A18: IF-02 | B18: Idoneidad funcional | C18: Corrección funcional | D18: RNF-01 exactitud | E18: evaluacion/oraculo.py + evaluacion/pruebas/oraculo.spec.js | F18: 08 | G18: v1.7 (b0ac637) | H18: 2026-10-27T12:06:18.210Z | I18: Windows_NT 10.0.26300 · Node v22.14.0 · Playwright Version 1.64.1 · Lighthouse 12.8.2 | J18: datos_abiertos_vigilancia_malaria_2000_2008.csv sha256:749d8897e94255d0; datos_abiertos_vigilancia_malaria_2009_2025.csv sha256:084ef118bd67753d | K18: proporcion | L18: 84 | M18: 84 | N18: X = A / B × 100 | O18: =IF(L18="","",IF(K18="proporcion",ROUND(L18/M18*100,2),L18)) -> 100 | P18: % | Q18: mayor | R18: 100 | S18: =IF(O18="","Pendiente",IF(Q18="mayor",IF(O18>=R18,"Aprobado","Rechazado"),IF(O18<=R18,"Aprobado","Rechazado"))) -> Aprobado | T18: =IF(O18="","",IF(K18="proporcion",O18,MIN(100,ROUND(100*R18/MAX(O18,0.000001),2)))) -> 100 | U18: =IF(T18="","",IF(T18<40,"No aceptable",IF(T18<60,"Mínimamente aceptable",IF(T18<90,"Rango objetivo","Supera los requisitos")))) -> Supera los requisitos | V18: evaluacion/resultados/corrida-08/if02-oraculo.json | W18: Chura Monroy, Daniel Wilston | Y18: Aceptar
A19: IF-02 | B19: Idoneidad funcional | C19: Corrección funcional | D19: RNF-01 exactitud | E19: evaluacion/oraculo.py + evaluacion/pruebas/oraculo.spec.js | F19: 09 | G19: v1.8 (ed65ebc) | H19: 2026-10-27T12:16:43.263Z | I19: Windows_NT 10.0.26300 · Node v22.14.0 · Playwright Version 1.64.1 · Lighthouse 12.8.2 | J19: datos_abiertos_vigilancia_malaria_2000_2008.csv sha256:749d8897e94255d0; datos_abiertos_vigilancia_malaria_2009_2025.csv sha256:084ef118bd67753d | K19: proporcion | L19: 84 | M19: 84 | N19: X = A / B × 100 | O19: =IF(L19="","",IF(K19="proporcion",ROUND(L19/M19*100,2),L19)) -> 100 | P19: % | Q19: mayor | R19: 100 | S19: =IF(O19="","Pendiente",IF(Q19="mayor",IF(O19>=R19,"Aprobado","Rechazado"),IF(O19<=R19,"Aprobado","Rechazado"))) -> Aprobado | T19: =IF(O19="","",IF(K19="proporcion",O19,MIN(100,ROUND(100*R19/MAX(O19,0.000001),2)))) -> 100 | U19: =IF(T19="","",IF(T19<40,"No aceptable",IF(T19<60,"Mínimamente aceptable",IF(T19<90,"Rango objetivo","Supera los requisitos")))) -> Supera los requisitos | V19: evaluacion/resultados/corrida-09/if02-oraculo.json | W19: Chura Monroy, Daniel Wilston | Y19: Aceptar
A20: IF-03 | B20: Idoneidad funcional | C20: Pertinencia funcional | D20: RNF-02 pertinencia | E20: Lista de verificación automatizada en interaccion.spec.js | F20: 01 | G20: v1.0 (e2ec6c9) | H20: 2026-10-27T05:09:45.825Z | I20: Windows_NT 10.0.26300 · Node v22.14.0 · Playwright Version 1.64.1 · Lighthouse 12.8.2 | J20: datos_abiertos_vigilancia_malaria_2000_2008.csv sha256:749d8897e94255d0; datos_abiertos_vigilancia_malaria_2009_2025.csv sha256:084ef118bd67753d | K20: proporcion | L20: 8 | M20: 8 | N20: X = A / B × 100 | O20: =IF(L20="","",IF(K20="proporcion",ROUND(L20/M20*100,2),L20)) -> 100 | P20: % | Q20: mayor | R20: 90 | S20: =IF(O20="","Pendiente",IF(Q20="mayor",IF(O20>=R20,"Aprobado","Rechazado"),IF(O20<=R20,"Aprobado","Rechazado"))) -> Aprobado | T20: =IF(O20="","",IF(K20="proporcion",O20,MIN(100,ROUND(100*R20/MAX(O20,0.000001),2)))) -> 100 | U20: =IF(T20="","",IF(T20<40,"No aceptable",IF(T20<60,"Mínimamente aceptable",IF(T20<90,"Rango objetivo","Supera los requisitos")))) -> Supera los requisitos | V20: evaluacion/resultados/corrida-01/interaccion.json, capturas/if03-dimensiones.png | W20: Chura Monroy, Daniel Wilston | Y20: Aceptar
A21: IF-03 | B21: Idoneidad funcional | C21: Pertinencia funcional | D21: RNF-02 pertinencia | E21: Lista de verificación automatizada en interaccion.spec.js | F21: 02 | G21: v1.1 (a63333f) | H21: 2026-10-27T05:22:39.464Z | I21: Windows_NT 10.0.26300 · Node v22.14.0 · Playwright Version 1.64.1 · Lighthouse 12.8.2 | J21: datos_abiertos_vigilancia_malaria_2000_2008.csv sha256:749d8897e94255d0; datos_abiertos_vigilancia_malaria_2009_2025.csv sha256:084ef118bd67753d | K21: proporcion | L21: 8 | M21: 8 | N21: X = A / B × 100 | O21: =IF(L21="","",IF(K21="proporcion",ROUND(L21/M21*100,2),L21)) -> 100 | P21: % | Q21: mayor | R21: 90 | S21: =IF(O21="","Pendiente",IF(Q21="mayor",IF(O21>=R21,"Aprobado","Rechazado"),IF(O21<=R21,"Aprobado","Rechazado"))) -> Aprobado | T21: =IF(O21="","",IF(K21="proporcion",O21,MIN(100,ROUND(100*R21/MAX(O21,0.000001),2)))) -> 100 | U21: =IF(T21="","",IF(T21<40,"No aceptable",IF(T21<60,"Mínimamente aceptable",IF(T21<90,"Rango objetivo","Supera los requisitos")))) -> Supera los requisitos | V21: evaluacion/resultados/corrida-02/interaccion.json, capturas/if03-dimensiones.png | W21: Chura Monroy, Daniel Wilston | Y21: Aceptar
... A24: IF-03 | B24: Idoneidad funcional | C24: Pertinencia funcional | D24: RNF-02 pertinencia | E24: Lista de verificación automatizada en interaccion.spec.js | F24: 05 | G24: v1.4 (ecd9c46) | H24: 2026-10-27T11:34:29.914Z | I24: Windows_NT 10.0.26300 · Node v22.14.0 · Playwright Version 1.64.1 · Lighthouse 12.8.2 | J24: datos_abiertos_vigilancia_malaria_2000_2008.csv sha256:749d8897e94255d0; datos_abiertos_vigilancia_malaria_2009_2025.csv sha256:084ef118bd67753d | K24: proporcion | L24: 8 | M24: 8 | N24: X = A / B × 100 | O24: =IF(L24="","",IF(K24="proporcion",ROUND(L24/M24*100,2),L24)) -> 100 | P24: % | Q24: mayor | R24: 90 | S24: =IF(O24="","Pendiente",IF(Q24="mayor",IF(O24>=R24,"Aprobado","Rechazado"),IF(O24<=R24,"Aprobado","Rechazado"))) -> Aprobado | T24: =IF(O24="","",IF(K24="proporcion",O24,MIN(100,ROUND(100*R24/MAX(O24,0.000001),2)))) -> 100 | U24: =IF(T24="","",IF(T24<40,"No aceptable",IF(T24<60,"Mínimamente aceptable",IF(T24<90,"Rango objetivo","Supera los requisitos")))) -> Supera los requisitos | V24: evaluacion/resultados/corrida-05/interaccion.json, capturas/if03-dimensiones.png | W24: Chura Monroy, Daniel Wilston | Y24: Aceptar
A25: IF-03 | B25: Idoneidad funcional | C25: Pertinencia funcional | D25: RNF-02 pertinencia | E25: Lista de verificación automatizada en interaccion.spec.js | F25: 06 | G25: v1.5 (2aca5a2) | H25: 2026-10-27T11:44:29.601Z | I25: Windows_NT 10.0.26300 · Node v22.14.0 · Playwright Version 1.64.1 · Lighthouse 12.8.2 | J25: datos_abiertos_vigilancia_malaria_2000_2008.csv sha256:749d8897e94255d0; datos_abiertos_vigilancia_malaria_2009_2025.csv sha256:084ef118bd67753d | K25: proporcion | L25: 8 | M25: 8 | N25: X = A / B × 100 | O25: =IF(L25="","",IF(K25="proporcion",ROUND(L25/M25*100,2),L25)) -> 100 | P25: % | Q25: mayor | R25: 90 | S25: =IF(O25="","Pendiente",IF(Q25="mayor",IF(O25>=R25,"Aprobado","Rechazado"),IF(O25<=R25,"Aprobado","Rechazado"))) -> Aprobado | T25: =IF(O25="","",IF(K25="proporcion",O25,MIN(100,ROUND(100*R25/MAX(O25,0.000001),2)))) -> 100 | U25: =IF(T25="","",IF(T25<40,"No aceptable",IF(T25<60,"Mínimamente aceptable",IF(T25<90,"Rango objetivo","Supera los requisitos")))) -> Supera los requisitos | V25: evaluacion/resultados/corrida-06/interaccion.json, capturas/if03-dimensiones.png | W25: Chura Monroy, Daniel Wilston | X25: INC-17, INC-19 | Y25: Se verificó que en departamento, provincia y distrito U+FFFD es el único carácter no ASCII y que las 31 palabras afectadas son topónimos con Ñ. El pipeline restituye la Ñ, lista los nombres corregidos en calidad_datos.json y el dashboard lo informa en «Datos y método». Todas las cifras quedaron idénticas (comparación completa de malaria.json antes y después). Se verifica en la corrida 07. La tarjeta usa una disposición apilada (etiqueta sobre valor). Se verifica en la corrida 07.
A26: IF-03 | B26: Idoneidad funcional | C26: Pertinencia funcional | D26: RNF-02 pertinencia | E26: Lista de verificación automatizada en interaccion.spec.js | F26: 07 | G26: v1.6 (f47b30f) | H26: 2026-10-27T11:55:54.129Z | I26: Windows_NT 10.0.26300 · Node v22.14.0 · Playwright Version 1.64.1 · Lighthouse 12.8.2 | J26: datos_abiertos_vigilancia_malaria_2000_2008.csv sha256:749d8897e94255d0; datos_abiertos_vigilancia_malaria_2009_2025.csv sha256:084ef118bd67753d | K26: proporcion | L26: 8 | M26: 8 | N26: X = A / B × 100 | O26: =IF(L26="","",IF(K26="proporcion",ROUND(L26/M26*100,2),L26)) -> 100 | P26: % | Q26: mayor | R26: 90 | S26: =IF(O26="","Pendiente",IF(Q26="mayor",IF(O26>=R26,"Aprobado","Rechazado"),IF(O26<=R26,"Aprobado","Rechazado"))) -> Aprobado | T26: =IF(O26="","",IF(K26="proporcion",O26,MIN(100,ROUND(100*R26/MAX(O26,0.000001),2)))) -> 100 | U26: =IF(T26="","",IF(T26<40,"No aceptable",IF(T26<60,"Mínimamente aceptable",IF(T26<90,"Rango objetivo","Supera los requisitos")))) -> Supera los requisitos | V26: evaluacion/resultados/corrida-07/interaccion.json, capturas/if03-dimensiones.png | W26: Chura Monroy, Daniel Wilston | Y26: Aceptar
A27: IF-03 | B27: Idoneidad funcional | C27: Pertinencia funcional | D27: RNF-02 pertinencia | E27: Lista de verificación automatizada en interaccion.spec.js | F27: 08 | G27: v1.7 (b0ac637) | H27: 2026-10-27T12:06:18.210Z | I27: Windows_NT 10.0.26300 · Node v22.14.0 · Playwright Version 1.64.1 · Lighthouse 12.8.2 | J27: datos_abiertos_vigilancia_malaria_2000_2008.csv sha256:749d8897e94255d0; datos_abiertos_vigilancia_malaria_2009_2025.csv sha256:084ef118bd67753d | K27: proporcion | L27: 8 | M27: 8 | N27: X = A / B × 100 | O27: =IF(L27="","",IF(K27="proporcion",ROUND(L27/M27*100,2),L27)) -> 100 | P27: % | Q27: mayor | R27: 90 | S27: =IF(O27="","Pendiente",IF(Q27="mayor",IF(O27>=R27,"Aprobado","Rechazado"),IF(O27<=R27,"Aprobado","Rechazado"))) -> Aprobado | T27: =IF(O27="","",IF(K27="proporcion",O27,MIN(100,ROUND(100*R27/MAX(O27,0.000001),2)))) -> 100 | U27: =IF(T27="","",IF(T27<40,"No aceptable",IF(T27<60,"Mínimamente aceptable",IF(T27<90,"Rango objetivo","Supera los requisitos")))) -> Supera los requisitos | V27: evaluacion/resultados/corrida-08/interaccion.json, capturas/if03-dimensiones.png | W27: Chura Monroy, Daniel Wilston | Y27: Aceptar
A28: IF-03 | B28: Idoneidad funcional | C28: Pertinencia funcional | D28: RNF-02 pertinencia | E28: Lista de verificación automatizada en interaccion.spec.js | F28: 09 | G28: v1.8 (ed65ebc) | H28: 2026-10-27T12:16:43.263Z | I28: Windows_NT 10.0.26300 · Node v22.14.0 · Playwright Version 1.64.1 · Lighthouse 12.8.2 | J28: datos_abiertos_vigilancia_malaria_2000_2008.csv sha256:749d8897e94255d0; datos_abiertos_vigilancia_malaria_2009_2025.csv sha256:084ef118bd67753d | K28: proporcion | L28: 8 | M28: 8 | N28: X = A / B × 100 | O28: =IF(L28="","",IF(K28="proporcion",ROUND(L28/M28*100,2),L28)) -> 100 | P28: % | Q28: mayor | R28: 90 | S28: =IF(O28="","Pendiente",IF(Q28="mayor",IF(O28>=R28,"Aprobado","Rechazado"),IF(O28<=R28,"Aprobado","Rechazado"))) -> Aprobado | T28: =IF(O28="","",IF(K28="proporcion",O28,MIN(100,ROUND(100*R28/MAX(O28,0.000001),2)))) -> 100 | U28: =IF(T28="","",IF(T28<40,"No aceptable",IF(T28<60,"Mínimamente aceptable",IF(T28<90,"Rango objetivo","Supera los requisitos")))) -> Supera los requisitos | V28: evaluacion/resultados/corrida-09/interaccion.json, capturas/if03-dimensiones.png | W28: Chura Monroy, Daniel Wilston | Y28: Aceptar
A29: ED-01 | B29: Eficiencia de desempeño | C29: Comportamiento temporal | D29: RNF-03 carga | E29: evaluacion/scripts/lighthouse.mjs | F29: 01 | G29: v1.0 (e2ec6c9) | H29: 2026-10-27T05:09:45.825Z | I29: Windows_NT 10.0.26300 · Node v22.14.0 · Playwright Version 1.64.1 · Lighthouse 12.8.2 | J29: datos_abiertos_vigilancia_malaria_2000_2008.csv sha256:749d8897e94255d0; datos_abiertos_vigilancia_malaria_2009_2025.csv sha256:084ef118bd67753d | K29: valor | L29: 3.291 | N29: X = valor medido | O29: =IF(L29="","",IF(K29="proporcion",ROUND(L29/M29*100,2),L29)) -> 3.291 | P29: s | Q29: menor | R29: 2.5 | S29: =IF(O29="","Pendiente",IF(Q29="mayor",IF(O29>=R29,"Aprobado","Rechazado"),IF(O29<=R29,"Aprobado","Rechazado"))) -> Rechazado | T29: =IF(O29="","",IF(K29="proporcion",O29,MIN(100,ROUND(100*R29/MAX(O29,0.000001),2)))) -> 75.96 | U29: =IF(T29="","",IF(T29<40,"No aceptable",IF(T29<60,"Mínimamente aceptable",IF(T29<90,"Rango objetivo","Supera los requisitos")))) -> Rango objetivo | V29: evaluacion/resultados/corrida-01/lighthouse.json, lighthouse.html | W29: Chura Monroy, Daniel Wilston | X29: INC-08 | Y29: Fuentes IBM Plex servidas desde el mismo origen (SIL OFL 1.1), precarga de la fuente principal y de los JSON de datos, y CSP restringida a font-src 'self'. Verificación en la corrida 02.
A30: ED-01 | B30: Eficiencia de desempeño | C30: Comportamiento temporal | D30: RNF-03 carga | E30: evaluacion/scripts/lighthouse.mjs | F30: 02 | G30: v1.1 (a63333f) | H30: 2026-10-27T05:22:39.464Z | I30: Windows_NT 10.0.26300 · Node v22.14.0 · Playwright Version 1.64.1 · Lighthouse 12.8.2 | J30: datos_abiertos_vigilancia_malaria_2000_2008.csv sha256:749d8897e94255d0; datos_abiertos_vigilancia_malaria_2009_2025.csv sha256:084ef118bd67753d | K30: valor | L30: 2.477 | N30: X = valor medido | O30: =IF(L30="","",IF(K30="proporcion",ROUND(L30/M30*100,2),L30)) -> 2.477 | P30: s | Q30: menor | R30: 2.5 | S30: =IF(O30="","Pendiente",IF(Q30="mayor",IF(O30>=R30,"Aprobado","Rechazado"),IF(O30<=R30,"Aprobado","Rechazado"))) -> Aprobado | T30: =IF(O30="","",IF(K30="proporcion",O30,MIN(100,ROUND(100*R30/MAX(O30,0.000001),2)))) -> 100 | U30: =IF(T30="","",IF(T30<40,"No aceptable",IF(T30<60,"Mínimamente aceptable",IF(T30<90,"Rango objetivo","Supera los requisitos")))) -> Supera los requisitos | V30: evaluacion/resultados/corrida-02/lighthouse.json, lighthouse.html | W30: Chura Monroy, Daniel Wilston | X30: INC-12 | Y30: Se precargan los cuatro pesos de IBM Plex Sans y se usa font-display: optional, que no recoloca el texto. La corrida 03 mostró que eso solo eliminó la parte atribuida a las fuentes (0,0001): la causa principal era otra y se registra en INC-13.
A31: ED-01 | B31: Eficiencia de desempeño | C31: Comportamiento temporal | D31: RNF-03 carga | E31: evaluacion/scripts/lighthouse.mjs | F31: 03 | G31: v1.2 (ecfaca3) | H31: 2026-10-27T11:13:27.260Z | I31: Windows_NT 10.0.26300 · Node v22.14.0 · Playwright Version 1.64.1 · Lighthouse 12.8.2 | J31: datos_abiertos_vigilancia_malaria_2000_2008.csv sha256:749d8897e94255d0; datos_abiertos_vigilancia_malaria_2009_2025.csv sha256:084ef118bd67753d | K31: valor | L31: 2.562 | N31: X = valor medido | O31: =IF(L31="","",IF(K31="proporcion",ROUND(L31/M31*100,2),L31)) -> 2.562 | P31: s | Q31: menor | R31: 2.5 | S31: =IF(O31="","Pendiente",IF(Q31="mayor",IF(O31>=R31,"Aprobado","Rechazado"),IF(O31<=R31,"Aprobado","Rechazado"))) -> Rechazado | T31: =IF(O31="","",IF(K31="proporcion",O31,MIN(100,ROUND(100*R31/MAX(O31,0.000001),2)))) -> 97.58 | U31: =IF(T31="","",IF(T31<40,"No aceptable",IF(T31<60,"Mínimamente aceptable",IF(T31<90,"Rango objetivo","Supera los requisitos")))) -> Supera los requisitos | V31: evaluacion/resultados/corrida-03/lighthouse.json, lighthouse.html | W31: Chura Monroy, Daniel Wilston | X31: INC-13, INC-14 | Y31: Se fijó grid-template-rows: auto 1fr en móvil, de modo que main absorbe el espacio libre y la barra no cambia de alto. En local, con red y CPU limitadas, el CLS bajó de 0,109 a 0,001. Se verifica en la corrida 04. El aviso queda en el HTML estático y se pinta antes de cargar los datos. La fecha de descarga va en una línea propia con altura reservada que se completa después (sin desplazamiento). En local, el LCP bajó de 2,7 s a 1,1 s. Se verifica en la corrida 04.
A32: ED-01 | B32: Eficiencia de desempeño | C32: Comportamiento temporal | D32: RNF-03 carga | E32: evaluacion/scripts/lighthouse.mjs | F32: 04 | G32: v1.3 (1219f7a) | H32: 2026-10-27T11:22:57.351Z | I32: Windows_NT 10.0.26300 · Node v22.14.0 · Playwright Version 1.64.1 · Lighthouse 12.8.2 | J32: datos_abiertos_vigilancia_malaria_2000_2008.csv sha256:749d8897e94255d0; datos_abiertos_vigilancia_malaria_2009_2025.csv sha256:084ef118bd67753d | K32: valor | L32: 2.55 | N32: X = valor medido | O32: =IF(L32="","",IF(K32="proporcion",ROUND(L32/M32*100,2),L32)) -> 2.55 | P32: s | Q32: menor | R32: 2.5 | S32: =IF(O32="","Pendiente",IF(Q32="mayor",IF(O32>=R32,"Aprobado","Rechazado"),IF(O32<=R32,"Aprobado","Rechazado"))) -> Rechazado | T32: =IF(O32="","",IF(K32="proporcion",O32,MIN(100,ROUND(100*R32/MAX(O32,0.000001),2)))) -> 98.04 | U32: =IF(T32="","",IF(T32<40,"No aceptable",IF(T32<60,"Mínimamente aceptable",IF(T32<90,"Rango objetivo","Supera los requisitos")))) -> Supera los requisitos | V32: evaluacion/resultados/corrida-04/lighthouse.json, lighthouse.html | W32: Chura Monroy, Daniel Wilston | X32: INC-15 | Y32: Se quitaron las precargas de datos y fuentes. D3 y los JSON se piden después del primer pintado con contenido (PerformanceObserver de tipo paint, con un tope de 500 ms). En local, con el mismo perfil de Lighthouse y sin compresión, el LCP simulado bajó de 5,56 s a 1,80 s. Se verifica en la corrida 05.
A33: ED-01 | B33: Eficiencia de desempeño | C33: Comportamiento temporal | D33: RNF-03 carga | E33: evaluacion/scripts/lighthouse.mjs | F33: 05 | G33: v1.4 (ecd9c46) | H33: 2026-10-27T11:34:29.914Z | I33: Windows_NT 10.0.26300 · Node v22.14.0 · Playwright Version 1.64.1 · Lighthouse 12.8.2 | J33: datos_abiertos_vigilancia_malaria_2000_2008.csv sha256:749d8897e94255d0; datos_abiertos_vigilancia_malaria_2009_2025.csv sha256:084ef118bd67753d | K33: valor | L33: 0.982 | N33: X = valor medido | O33: =IF(L33="","",IF(K33="proporcion",ROUND(L33/M33*100,2),L33)) -> 0.982 | P33: s | Q33: menor | R33: 2.5 | S33: =IF(O33="","Pendiente",IF(Q33="mayor",IF(O33>=R33,"Aprobado","Rechazado"),IF(O33<=R33,"Aprobado","Rechazado"))) -> Aprobado | T33: =IF(O33="","",IF(K33="proporcion",O33,MIN(100,ROUND(100*R33/MAX(O33,0.000001),2)))) -> 100 | U33: =IF(T33="","",IF(T33<40,"No aceptable",IF(T33<60,"Mínimamente aceptable",IF(T33<90,"Rango objetivo","Supera los requisitos")))) -> Supera los requisitos | V33: evaluacion/resultados/corrida-05/lighthouse.json, lighthouse.html | W33: Chura Monroy, Daniel Wilston | Y33: Aceptar
A34: ED-01 | B34: Eficiencia de desempeño | C34: Comportamiento temporal | D34: RNF-03 carga | E34: evaluacion/scripts/lighthouse.mjs | F34: 06 | G34: v1.5 (2aca5a2) | H34: 2026-10-27T11:44:29.601Z | I34: Windows_NT 10.0.26300 · Node v22.14.0 · Playwright Version 1.64.1 · Lighthouse 12.8.2 | J34: datos_abiertos_vigilancia_malaria_2000_2008.csv sha256:749d8897e94255d0; datos_abiertos_vigilancia_malaria_2009_2025.csv sha256:084ef118bd67753d | K34: valor | L34: 0.983 | N34: X = valor medido | O34: =IF(L34="","",IF(K34="proporcion",ROUND(L34/M34*100,2),L34)) -> 0.983 | P34: s | Q34: menor | R34: 2.5 | S34: =IF(O34="","Pendiente",IF(Q34="mayor",IF(O34>=R34,"Aprobado","Rechazado"),IF(O34<=R34,"Aprobado","Rechazado"))) -> Aprobado | T34: =IF(O34="","",IF(K34="proporcion",O34,MIN(100,ROUND(100*R34/MAX(O34,0.000001),2)))) -> 100 | U34: =IF(T34="","",IF(T34<40,"No aceptable",IF(T34<60,"Mínimamente aceptable",IF(T34<90,"Rango objetivo","Supera los requisitos")))) -> Supera los requisitos | V34: evaluacion/resultados/corrida-06/lighthouse.json, lighthouse.html | W34: Chura Monroy, Daniel Wilston | Y34: Aceptar
A35: ED-01 | B35: Eficiencia de desempeño | C35: Comportamiento temporal | D35: RNF-03 carga | E35: evaluacion/scripts/lighthouse.mjs | F35: 07 | G35: v1.6 (f47b30f) | H35: 2026-10-27T11:55:54.129Z | I35: Windows_NT 10.0.26300 · Node v22.14.0 · Playwright Version 1.64.1 · Lighthouse 12.8.2 | J35: datos_abiertos_vigilancia_malaria_2000_2008.csv sha256:749d8897e94255d0; datos_abiertos_vigilancia_malaria_2009_2025.csv sha256:084ef118bd67753d | K35: valor | L35: 0.982 | N35: X = valor medido | O35: =IF(L35="","",IF(K35="proporcion",ROUND(L35/M35*100,2),L35)) -> 0.982 | P35: s | Q35: menor | R35: 2.5 | S35: =IF(O35="","Pendiente",IF(Q35="mayor",IF(O35>=R35,"Aprobado","Rechazado"),IF(O35<=R35,"Aprobado","Rechazado"))) -> Aprobado | T35: =IF(O35="","",IF(K35="proporcion",O35,MIN(100,ROUND(100*R35/MAX(O35,0.000001),2)))) -> 100 | U35: =IF(T35="","",IF(T35<40,"No aceptable",IF(T35<60,"Mínimamente aceptable",IF(T35<90,"Rango objetivo","Supera los requisitos")))) -> Supera los requisitos | V35: evaluacion/resultados/corrida-07/lighthouse.json, lighthouse.html | W35: Chura Monroy, Daniel Wilston | Y35: Aceptar
A36: ED-01 | B36: Eficiencia de desempeño | C36: Comportamiento temporal | D36: RNF-03 carga | E36: evaluacion/scripts/lighthouse.mjs | F36: 08 | G36: v1.7 (b0ac637) | H36: 2026-10-27T12:06:18.210Z | I36: Windows_NT 10.0.26300 · Node v22.14.0 · Playwright Version 1.64.1 · Lighthouse 12.8.2 | J36: datos_abiertos_vigilancia_malaria_2000_2008.csv sha256:749d8897e94255d0; datos_abiertos_vigilancia_malaria_2009_2025.csv sha256:084ef118bd67753d | K36: valor | L36: 0.982 | N36: X = valor medido | O36: =IF(L36="","",IF(K36="proporcion",ROUND(L36/M36*100,2),L36)) -> 0.982 | P36: s | Q36: menor | R36: 2.5 | S36: =IF(O36="","Pendiente",IF(Q36="mayor",IF(O36>=R36,"Aprobado","Rechazado"),IF(O36<=R36,"Aprobado","Rechazado"))) -> Aprobado | T36: =IF(O36="","",IF(K36="proporcion",O36,MIN(100,ROUND(100*R36/MAX(O36,0.000001),2)))) -> 100 | U36: =IF(T36="","",IF(T36<40,"No aceptable",IF(T36<60,"Mínimamente aceptable",IF(T36<90,"Rango objetivo","Supera los requisitos")))) -> Supera los requisitos | V36: evaluacion/resultados/corrida-08/lighthouse.json, lighthouse.html | W36: Chura Monroy, Daniel Wilston | Y36: Aceptar
A37: ED-01 | B37: Eficiencia de desempeño | C37: Comportamiento temporal | D37: RNF-03 carga | E37: evaluacion/scripts/lighthouse.mjs | F37: 09 | G37: v1.8 (ed65ebc) | H37: 2026-10-27T12:16:43.263Z | I37: Windows_NT 10.0.26300 · Node v22.14.0 · Playwright Version 1.64.1 · Lighthouse 12.8.2 | J37: datos_abiertos_vigilancia_malaria_2000_2008.csv sha256:749d8897e94255d0; datos_abiertos_vigilancia_malaria_2009_2025.csv sha256:084ef118bd67753d | K37: valor | L37: 0.983 | N37: X = valor medido | O37: =IF(L37="","",IF(K37="proporcion",ROUND(L37/M37*100,2),L37)) -> 0.983 | P37: s | Q37: menor | R37: 2.5 | S37: =IF(O37="","Pendiente",IF(Q37="mayor",IF(O37>=R37,"Aprobado","Rechazado"),IF(O37<=R37,"Aprobado","Rechazado"))) -> Aprobado | T37: =IF(O37="","",IF(K37="proporcion",O37,MIN(100,ROUND(100*R37/MAX(O37,0.000001),2)))) -> 100 | U37: =IF(T37="","",IF(T37<40,"No aceptable",IF(T37<60,"Mínimamente aceptable",IF(T37<90,"Rango objetivo","Supera los requisitos")))) -> Supera los requisitos | V37: evaluacion/resultados/corrida-09/lighthouse.json, lighthouse.html | W37: Chura Monroy, Daniel Wilston | Y37: Aceptar
A38: ED-02 | B38: Eficiencia de desempeño | C38: Comportamiento temporal | D38: RNF-03 respuesta | E38: evaluacion/pruebas/rendimiento.spec.js | F38: 01 | G38: v1.0 (e2ec6c9) | H38: 2026-10-27T05:09:45.825Z | I38: Windows_NT 10.0.26300 · Node v22.14.0 · Playwright Version 1.64.1 · Lighthouse 12.8.2 | J38: datos_abiertos_vigilancia_malaria_2000_2008.csv sha256:749d8897e94255d0; datos_abiertos_vigilancia_malaria_2009_2025.csv sha256:084ef118bd67753d | K38: valor | L38: 42.8 | N38: X = valor medido | O38: =IF(L38="","",IF(K38="proporcion",ROUND(L38/M38*100,2),L38)) -> 42.8 | P38: ms | Q38: menor | R38: 200 | S38: =IF(O38="","Pendiente",IF(Q38="mayor",IF(O38>=R38,"Aprobado","Rechazado"),IF(O38<=R38,"Aprobado","Rechazado"))) -> Aprobado | T38: =IF(O38="","",IF(K38="proporcion",O38,MIN(100,ROUND(100*R38/MAX(O38,0.000001),2)))) -> 100 | U38: =IF(T38="","",IF(T38<40,"No aceptable",IF(T38<60,"Mínimamente aceptable",IF(T38<90,"Rango objetivo","Supera los requisitos")))) -> Supera los requisitos | V38: evaluacion/resultados/corrida-01/ed02-respuesta.json | W38: Chura Monroy, Daniel Wilston | Y38: Aceptar
A39: ED-02 | B39: Eficiencia de desempeño | C39: Comportamiento temporal | D39: RNF-03 respuesta | E39: evaluacion/pruebas/rendimiento.spec.js | F39: 02 | G39: v1.1 (a63333f) | H39: 2026-10-27T05:22:39.464Z | I39: Windows_NT 10.0.26300 · Node v22.14.0 · Playwright Version 1.64.1 · Lighthouse 12.8.2 | J39: datos_abiertos_vigilancia_malaria_2000_2008.csv sha256:749d8897e94255d0; datos_abiertos_vigilancia_malaria_2009_2025.csv sha256:084ef118bd67753d | K39: valor | L39: 42.4 | N39: X = valor medido | O39: =IF(L39="","",IF(K39="proporcion",ROUND(L39/M39*100,2),L39)) -> 42.4 | P39: ms | Q39: menor | R39: 200 | S39: =IF(O39="","Pendiente",IF(Q39="mayor",IF(O39>=R39,"Aprobado","Rechazado"),IF(O39<=R39,"Aprobado","Rechazado"))) -> Aprobado | T39: =IF(O39="","",IF(K39="proporcion",O39,MIN(100,ROUND(100*R39/MAX(O39,0.000001),2)))) -> 100 | U39: =IF(T39="","",IF(T39<40,"No aceptable",IF(T39<60,"Mínimamente aceptable",IF(T39<90,"Rango objetivo","Supera los requisitos")))) -> Supera los requisitos | V39: evaluacion/resultados/corrida-02/ed02-respuesta.json | W39: Chura Monroy, Daniel Wilston | Y39: Aceptar
A40: ED-02 | B40: Eficiencia de desempeño | C40: Comportamiento temporal | D40: RNF-03 respuesta | E40: evaluacion/pruebas/rendimiento.spec.js | F40: 03 | G40: v1.2 (ecfaca3) | H40: 2026-10-27T11:13:27.260Z | I40: Windows_NT 10.0.26300 · Node v22.14.0 · Playwright Version 1.64.1 · Lighthouse 12.8.2 | J40: datos_abiertos_vigilancia_malaria_2000_2008.csv sha256:749d8897e94255d0; datos_abiertos_vigilancia_malaria_2009_2025.csv sha256:084ef118bd67753d | K40: valor | L40: 38.5 | N40: X = valor medido | O40: =IF(L40="","",IF(K40="proporcion",ROUND(L40/M40*100,2),L40)) -> 38.5 | P40: ms | Q40: menor | R40: 200 | S40: =IF(O40="","Pendiente",IF(Q40="mayor",IF(O40>=R40,"Aprobado","Rechazado"),IF(O40<=R40,"Aprobado","Rechazado"))) -> Aprobado | T40: =IF(O40="","",IF(K40="proporcion",O40,MIN(100,ROUND(100*R40/MAX(O40,0.000001),2)))) -> 100 | U40: =IF(T40="","",IF(T40<40,"No aceptable",IF(T40<60,"Mínimamente aceptable",IF(T40<90,"Rango objetivo","Supera los requisitos")))) -> Supera los requisitos | V40: evaluacion/resultados/corrida-03/ed02-respuesta.json | W40: Chura Monroy, Daniel Wilston | Y40: Aceptar
A41: ED-02 | B41: Eficiencia de desempeño | C41: Comportamiento temporal | D41: RNF-03 respuesta | E41: evaluacion/pruebas/rendimiento.spec.js | F41: 04 | G41: v1.3 (1219f7a) | H41: 2026-10-27T11:22:57.351Z | I41: Windows_NT 10.0.26300 · Node v22.14.0 · Playwright Version 1.64.1 · Lighthouse 12.8.2 | J41: datos_abiertos_vigilancia_malaria_2000_2008.csv sha256:749d8897e94255d0; datos_abiertos_vigilancia_malaria_2009_2025.csv sha256:084ef118bd67753d | K41: valor | L41: 38.5 | N41: X = valor medido | O41: =IF(L41="","",IF(K41="proporcion",ROUND(L41/M41*100,2),L41)) -> 38.5 | P41: ms | Q41: menor | R41: 200 | S41: =IF(O41="","Pendiente",IF(Q41="mayor",IF(O41>=R41,"Aprobado","Rechazado"),IF(O41<=R41,"Aprobado","Rechazado"))) -> Aprobado | T41: =IF(O41="","",IF(K41="proporcion",O41,MIN(100,ROUND(100*R41/MAX(O41,0.000001),2)))) -> 100 | U41: =IF(T41="","",IF(T41<40,"No aceptable",IF(T41<60,"Mínimamente aceptable",IF(T41<90,"Rango objetivo","Supera los requisitos")))) -> Supera los requisitos | V41: evaluacion/resultados/corrida-04/ed02-respuesta.json | W41: Chura Monroy, Daniel Wilston | Y41: Aceptar
A42: ED-02 | B42: Eficiencia de desempeño | C42: Comportamiento temporal | D42: RNF-03 respuesta | E42: evaluacion/pruebas/rendimiento.spec.js | F42: 05 | G42: v1.4 (ecd9c46) | H42: 2026-10-27T11:34:29.914Z | I42: Windows_NT 10.0.26300 · Node v22.14.0 · Playwright Version 1.64.1 · Lighthouse 12.8.2 | J42: datos_abiertos_vigilancia_malaria_2000_2008.csv sha256:749d8897e94255d0; datos_abiertos_vigilancia_malaria_2009_2025.csv sha256:084ef118bd67753d | K42: valor | L42: 36.9 | N42: X = valor medido | O42: =IF(L42="","",IF(K42="proporcion",ROUND(L42/M42*100,2),L42)) -> 36.9 | P42: ms | Q42: menor | R42: 200 | S42: =IF(O42="","Pendiente",IF(Q42="mayor",IF(O42>=R42,"Aprobado","Rechazado"),IF(O42<=R42,"Aprobado","Rechazado"))) -> Aprobado | T42: =IF(O42="","",IF(K42="proporcion",O42,MIN(100,ROUND(100*R42/MAX(O42,0.000001),2)))) -> 100 | U42: =IF(T42="","",IF(T42<40,"No aceptable",IF(T42<60,"Mínimamente aceptable",IF(T42<90,"Rango objetivo","Supera los requisitos")))) -> Supera los requisitos | V42: evaluacion/resultados/corrida-05/ed02-respuesta.json | W42: Chura Monroy, Daniel Wilston | Y42: Aceptar
...

Sheet Incidentes
A1: ID | B1: Corrida | C1: Métrica | D1: Descripción | E1: Origen | F1: Severidad | G1: Estado | H1: Decisión | I1: Responsable | J1: Evidencia
A2: INC-01 | B2: 01 | C2: CI-03 | D2: axe-core (regla label-content-name-mismatch, impacto serious): el enlace del logotipo tiene aria-label «VigiSalud Malaria», que no contiene el texto visible «VigiSalud Malaria · Perú». Afecta al dashboard (ES, EN y vista filtrada) y al tablero de calidad. | E2: producto | F2: media | G2: resuelto | H2: Se retiró el aria-label para que el nombre accesible sea el texto visible. Verificado en la corrida 02. | I2: I3 | J2: evaluacion/resultados/corrida-01/ci03-axe.json; evaluacion/resultados/corrida-01/playwright.json
A3: INC-02 | B3: 01 | C3: CI-03 | D3: axe-core (regla scrollable-region-focusable, impacto serious): los contenedores de tabla con desplazamiento (#tbAnual, #tbCanal y la tabla de subcaracterísticas no aplicables del tablero) no pueden recibir el foco, por lo que no se pueden desplazar con el teclado. | E3: producto | F3: alta | G3: resuelto | H3: comun.js asigna tabindex=0, role=region y un aria-label traducido a cada .tablewrap. Verificado en la corrida 02. | I3: I3 | J3: evaluacion/resultados/corrida-01/playwright.json
